Workbook

Sheet Read me
B2: Verdigris — Economics Model: traditional bridging lender vs AI-native lender
B4: Purpose: compare the cost structure of a typical mid-size UK bridging lender ('Northgate Bridging', a fictional composite) with an AI-native lender ('Verdigris') running the SAME loan book, then show how each scales.
B6: How to use
B7: • Blue text = input you can change. Yellow fill = the key assumptions that drive the answer. Black = formula. Green = link from another sheet.
B8: • Change inputs only on the 'Assumptions' sheet and the two Headcount sheets. Everything else recalculates.
B9: • Every input has a cell comment saying where it came from (public source, founder estimate, or research benchmark). Hover to read it.
B11: Sheets
B12: 1. Assumptions — loan book, pricing, fees, funding cost, losses, on-costs, AI cost per case.
B13: 2. Headcount — Traditional — 37-person team by function, salary, bonus, fully loaded cost.
B14: 3. Headcount — AI-native — 8-person team doing the same book with AI agents.
B15: 4. Salary benchmarks — industry ranges (low / mid / high) next to the figures used.
B16: 5. Revenue — revenue build for the loan book (identical for both models).
... B29: Built 9 September 2026.

Sheet Assumptions
B2: Assumptions — all inputs in blue; yellow = key drivers
B4: Item | C4: Value | D4: Unit | E4: Basis / source
B5: LOAN BOOK
B6: Live loan book (average) | C6: 150000000 | D6: £ | E6: Founder estimate for a ~35-person lender; consistent with £3–10m book per employee benchmark (Octane, Hope, Tuscan) and est. £120–320m for the comparator.
B7: Bridging / refurbishment: average loan size | C7: 650000 | D7: £ | E7: Founder: funded by the institutional partner, normally up to £1m; typical property £500–800k. Pipeline tracker Jan 2026: facilities £205k–£1.59m, median ≈ £440k.
B8: Ground-up development: average loan size | C8: 1250000 | D8: £ | E8: Founder: funded by the bank partner, typically £1m–£1.5m; a growing share of the book.
B9: Share of originations that are ground-up development | C9: 0.3 | D9: % by count | E9: Founder: 'getting more of those'; 30% assumed. Change to reflect the current mix.
B10: Blended average loan size | C10: =C7*(1-C9)+C8*C9 -> 830000 | D10: £ | E10: Weighted by product mix.
B11: Average term | C11: 12 | D11: months | E11: Bridging Trends 2025 average term 12 months; founder calculator example 18 months (refurb).
B12: Loans completed per year | C12: =ROUND(C6/C10*12/C11,0) -> 181 | D12: loans | E12: Book ÷ blended loan × 12 ÷ term. With 10 in credit ≈ 19 per underwriter, versus founder's ~25/yr as an analyst.
B13: Annual originations (£) | C13: =C12*C10 -> 150230000 | D13: £ | E13: Loans × blended average loan size.
B14: Applications assessed per completed loan | C14: 4 | D14: x | E14: Founder estimate: pipeline of 15–25 live cases vs ~2 completions/month per analyst → roughly 1 in 4 assessed cases completes.
B15: Cases assessed per year | C15: =C12*C14 -> 724 | D15: cases | E15: Every assessed case costs underwriting effort whether or not it completes.
B16: PRICING & REVENUE
B17: Borrower interest rate (monthly) | C17: 0.009 | D17: % / month | E17: Founder calculator: 0.95%/month fixed on a medium refurb (variable option BoE 4.25% + 0.51%/mo = 10.37% pa). Market average 0.81–0.84% (Bridging Trends). 0.90% blended used.
B18: Borrower interest rate (annualised, simple) | C18: =C17*12 -> 0.108 | D18: % pa | E18: Simple ×12. Founder calculator effective rate 11.98% pa on 0.95%/mo.
B19: Arrangement fee charged to borrower | C19: 0.02 | D19: % of loan | E19: Founder calculator: 2% of gross loan ('Lender & Broker Fee').
B20: Arrangement fee retained by lender (after introducer share) | C20: 0.005 | D20: % of loan | E20: Founder calculator: on the example deal 0% retained, 2% paid as 'introducer share'. Founder: broker payout 1–2%. 0.5% retained assumed — change if your typical split differs.
B21: Admin fee per loan (retained) | C21: 1500 | D21: £ | E21: Founder calculator: £1,995 (<£100k), £1,500 (£100–250k), £1,250 (>£250k) automatic admin fee. £1,500 blended.
B22: Redemption + drawdown fees per loan | C22: 1500 | D22: £ | E22: Founder calculator: redemption fee £495; drawdown fee £295/month on refurb/development. ~£1,500 per loan blended.
B23: Exit fee | C23: 0 | D23: % of loan | E23: Founder calculator: 0%. Some lenders charge 0–1%.
B24: Other fees (extension, variation, non-redemption) | C24: 0.002 | D24: % of originations | E24: Founder estimate; extension/variation fees exist but are not systematic.
B25: Share of loans introduced by brokers | C25: 0.85 | D25: % | E25: BDLA/Interpath 2026 survey: 61% of lenders name brokers as primary channel, 15% direct → ~85% broker-introduced. Broker fee is already netted in 'retained' above.
B26: FUNDING & RISK
B27: Funding partner buy rate (cost of funds, annual) | C27: 0.0875 | D27: % pa | E27: Founder calculator rate card: institutional partner 8.25–9.75% depending on product and advance rate (8.75% on the example); bank line = BoE + 4.3–4.8%. 8.75% used.
B28: Share of book funded by partners | C28: 0.95 | D28: % | E28: Founder calculator: partner advance rate 95%, lender first-loss 5%.
B29: Funder fee per loan | C29: 500 | D29: £ | E29: Founder calculator: £500 partner fee per deal.
B30: Expected credit loss (annual, % of book) | C30: 0.005 | D30: % pa | E30: Founder estimate; comparator claims 0 capital losses over 7 years; BDLA default rates typically <1%. 0.5% is prudent.
B31: EMPLOYMENT ON-COSTS (2026/27)
B32: Employer National Insurance rate | C32: 0.15 | D32: % | E32: 15% above secondary threshold (unchanged from April 2025).
B33: NI secondary threshold | C33: 5000 | D33: £ pa | E33: £5,000 per employee per year, frozen to 2030–31.
B34: Employer pension contribution | C34: 0.05 | D34: % of salary | E34: Auto-enrolment minimum 3%; 5% typical for a financial-services employer.
B35: Other on-costs (benefits, kit, recruitment, software seats) | C35: 0.08 | D35: % of salary | E35: All-in multiplier 1.25–1.4x is typical (Grove HR); NI 15% + pension 5% + 8% other ≈ 1.28x.
B36: Office cost per desk per year | C36: 9600 | D36: £ pa | E36: London serviced office £700–900/desk/month City; £800 used.
B37: Software & data per employee per year | C37: 3000 | D37: £ pa | E37: CRM/LOS seat £1–3k plus general tooling.
B38: AI-NATIVE OPERATING COSTS
B39: Model (LLM) cost per assessed case | C39: 16 | D39: £ | E39: Anthropic list prices Jun 2026: Opus 5 $5/$25 per M tokens; ~300k input + 20k output tokens per case ≈ $2. ×10 safety factor for retries, tools, re-underwrites, evals = $20 ≈ £16 at $1.30/£.
B40: Data & verification per assessed case | C40: 50 | D40: £ | E40: Land Registry £7/doc (£14–28), KYC £2–6, company credit £5–15, AVM £10–25, consumer credit £1–5 → £40–80.
B41: Platform, hosting, monitoring per year | C41: 60000 | D41: £ pa | E41: Founder estimate: cloud, observability, model evals, security tooling for a regulated lender.
B42: Human review time per assessed case (AI-native) | C42: 1.5 | D42: hours | E42: Underwriter reviews the AI-drafted pack and decides. Founder estimate.
...

Sheet Headcount - Traditional
B2: Northgate Bridging (composite) — 37-person traditional lender
B3: Team shape from founder's knowledge of a typical mid-size lender: 10 credit, 8 portfolio, 6 sales, 4 marketing, 5 management, 4 tech. Salaries = London 2025–26 benchmarks (see Sources).
B5: Function | C5: Role | D5: FTE | E5: Base salary (each) | F5: Bonus % | G5: Base total | H5: Bonus total | I5: Employer NI | J5: Pension + other | K5: Fully loaded cost | L5: Basis
B6: Credit | C6: Head of Credit | D6: 1 | E6: 115000 | F6: 0.25 | G6: =D6*E6 -> 115000 | H6: =G6*F6 -> 28750 | I6: =MAX(0,(E6+E6*F6)-Assumptions!$C$33)*Assumptions!$C$32*D6 -> 20812.5 | J6: =(G6+H6)*(Assumptions!$C$34+Assumptions!$C$35) -> 18687.5 | K6: =G6+H6+I6+J6 -> 183250 | L6: Head of Credit, bridging/dev lender London £100–130k (jobsite; Morgan McKinley). EST.
B7: Credit | C7: Senior underwriter (bridging + development) | D7: 2 | E7: 65000 | F7: 0.15 | G7: =D7*E7 -> 130000 | H7: =G7*F7 -> 19500 | I7: =MAX(0,(E7+E7*F7)-Assumptions!$C$33)*Assumptions!$C$32*D7 -> 20925 | J7: =(G7+H7)*(Assumptions!$C$34+Assumptions!$C$35) -> 19435 | K7: =G7+H7+I7+J7 -> 189860 | L7: Founder: analysts normally under £55k; seniors above. Market ads: senior bridging UW £65–80k (exec-appointments; Fintelligent). £65k used.
B8: Credit | C8: Credit analyst / underwriter (mid) | D8: 4 | E8: 50000 | F8: 0.1 | G8: =D8*E8 -> 200000 | H8: =G8*F8 -> 20000 | I8: =MAX(0,(E8+E8*F8)-Assumptions!$C$33)*Assumptions!$C$32*D8 -> 30000 | J8: =(G8+H8)*(Assumptions!$C$34+Assumptions!$C$35) -> 28600 | K8: =G8+H8+I8+J8 -> 278600 | L8: Founder: credit analysts normally under £55k. Market ads: £45–65k + 10–20% (Tandem; Fintelligent). £50k used.
B9: Credit | C9: Junior credit analyst | D9: 3 | E9: 35000 | F9: 0.05 | G9: =D9*E9 -> 105000 | H9: =G9*F9 -> 5250 | I9: =MAX(0,(E9+E9*F9)-Assumptions!$C$33)*Assumptions!$C$32*D9 -> 14287.5 | J9: =(G9+H9)*(Assumptions!$C$34+Assumptions!$C$35) -> 14332.5 | K9: =G9+H9+I9+J9 -> 138870 | L9: Junior bridging UW £30–45k (Fame Recruitment ad; talent.com); founder: under £55k for analysts. £35k used.
B10: Portfolio | C10: Portfolio manager | D10: 1 | E10: 57500 | F10: 0.125 | G10: =D10*E10 -> 57500 | H10: =G10*F10 -> 7187.5 | I10: =MAX(0,(E10+E10*F10)-Assumptions!$C$33)*Assumptions!$C$32*D10 -> 8953.125 | J10: =(G10+H10)*(Assumptions!$C$34+Assumptions!$C$35) -> 8409.375 | K10: =G10+H10+I10+J10 -> 82050 | L10: Portfolio Manager bridging up to £60–65k + bonus (Reed; Fintelligent).
B11: Portfolio | C11: Completions / case manager | D11: 3 | E11: 42500 | F11: 0.05 | G11: =D11*E11 -> 127500 | H11: =G11*F11 -> 6375 | I11: =MAX(0,(E11+E11*F11)-Assumptions!$C$33)*Assumptions!$C$32*D11 -> 17831.25 | J11: =(G11+H11)*(Assumptions!$C$34+Assumptions!$C$35) -> 17403.75 | K11: =G11+H11+I11+J11 -> 169110 | L11: Completions specialist up to £40k (+London uplift); case manager £30–35k (NRG).
B12: Portfolio | C12: Loan administrator / servicing | D12: 4 | E12: 32000 | F12: 0.025 | G12: =D12*E12 -> 128000 | H12: =G12*F12 -> 3200 | I12: =MAX(0,(E12+E12*F12)-Assumptions!$C$33)*Assumptions!$C$32*D12 -> 16680 | J12: =(G12+H12)*(Assumptions!$C$34+Assumptions!$C$35) -> 17056 | K12: =G12+H12+I12+J12 -> 164936 | L12: Loan admin £26–38k London (Indeed; PayScale).
B13: Sales | C13: Head of Sales | D13: 1 | E13: 110000 | F13: 0.35 | G13: =D13*E13 -> 110000 | H13: =G13*F13 -> 38500 | I13: =MAX(0,(E13+E13*F13)-Assumptions!$C$33)*Assumptions!$C$32*D13 -> 21525 | J13: =(G13+H13)*(Assumptions!$C$34+Assumptions!$C$35) -> 19305 | K13: =G13+H13+I13+J13 -> 189330 | L13: Head of Sales London avg £104k, 30–40% variable (Glassdoor; sales-director norm). EST.
B14: Sales | C14: Senior BDM / originator | D14: 2 | E14: 85000 | F14: 0.6 | G14: =D14*E14 -> 170000 | H14: =G14*F14 -> 102000 | I14: =MAX(0,(E14+E14*F14)-Assumptions!$C$33)*Assumptions!$C$32*D14 -> 39300 | J14: =(G14+H14)*(Assumptions!$C$34+Assumptions!$C$35) -> 35360 | K14: =G14+H14+I14+J14 -> 346660 | L14: Originator £75–85k + bonus up to 100% (Fintelligent); £90k + uncapped (jobsite).
B15: Sales | C15: BDM | D15: 3 | E15: 65000 | F15: 0.4 | G15: =D15*E15 -> 195000 | H15: =G15*F15 -> 78000 | I15: =MAX(0,(E15+E15*F15)-Assumptions!$C$33)*Assumptions!$C$32*D15 -> 38700 | J15: =(G15+H15)*(Assumptions!$C$34+Assumptions!$C$35) -> 35490 | K15: =G15+H15+I15+J15 -> 347190 | L15: BDM bridging up to £65k + 20% bonus; £60–80k + OTE 1.3–1.8x (Fintelligent; Totaljobs).
B16: Marketing | C16: Marketing manager | D16: 1 | E16: 48000 | F16: 0.075 | G16: =D16*E16 -> 48000 | H16: =G16*F16 -> 3600 | I16: =MAX(0,(E16+E16*F16)-Assumptions!$C$33)*Assumptions!$C$32*D16 -> 6990 | J16: =(G16+H16)*(Assumptions!$C$34+Assumptions!$C$35) -> 6708 | K16: =G16+H16+I16+J16 -> 65298 | L16: Marketing manager London avg £48k (Glassdoor).
B17: Marketing | C17: Marketing executive | D17: 3 | E17: 36000 | F17: 0.025 | G17: =D17*E17 -> 108000 | H17: =G17*F17 -> 2700 | I17: =MAX(0,(E17+E17*F17)-Assumptions!$C$33)*Assumptions!$C$32*D17 -> 14355 | J17: =(G17+H17)*(Assumptions!$C$34+Assumptions!$C$35) -> 14391 | K17: =G17+H17+I17+J17 -> 139446 | L17: Marketing executive London avg £36k (Glassdoor).
... B23: Technology | C23: Software engineer / IT | D23: 4 | E23: 65000 | F23: 0.05 | G23: =D23*E23 -> 260000 | H23: =G23*F23 -> 13000 | I23: =MAX(0,(E23+E23*F23)-Assumptions!$C$33)*Assumptions!$C$32*D23 -> 37950 | J23: =(G23+H23)*(Assumptions!$C$34+Assumptions!$C$35) -> 35490 | K23: =G23+H23+I23+J23 -> 346440 | L23: Software engineer London mid £50–80k (Glassdoor).
B24: TOTAL PEOPLE COST | D24: =SUM(D6:D23) -> 37 | G24: =SUM(G6:G23) -> 2376500 | H24: =SUM(H6:H23) -> 487750 | I24: =SUM(I6:I23) -> 401887.5 | J24: =SUM(J6:J23) -> 372352.5 | K24: =SUM(K6:K23) -> 3638490
B26: Office (desks × cost per desk) | K26: =D24*Assumptions!$C$36 -> 355200
B27: Software & data seats | K27: =D24*Assumptions!$C$37 -> 111000
B28: Data & verification (cases × £ per case) | K28: =Assumptions!$C$15*Assumptions!$C$40 -> 36200

Sheet Headcount - AI-native
B2: Verdigris — 8-person AI-native lender running the same book
B3: AI agents do document reading, extraction, reconciliation, drafting, chasing and monitoring. Humans decide, sign off, and own relationships and compliance.
B5: Function | C5: Role | D5: FTE | E5: Base salary (each) | F5: Bonus % | G5: Base total | H5: Bonus total | I5: Employer NI | J5: Pension + other | K5: Fully loaded cost | L5: Basis
B6: Leadership | C6: CEO / Head of Credit (founder, underwrites) | D6: 1 | E6: 100000 | F6: 0 | G6: =D6*E6 -> 100000 | H6: =G6*F6 -> 0 | I6: =MAX(0,(E6+E6*F6)-Assumptions!$C$33)*Assumptions!$C$32*D6 -> 14250 | J6: =(G6+H6)*(Assumptions!$C$34+Assumptions!$C$35) -> 13000 | K6: =G6+H6+I6+J6 -> 127250 | L6: Founder salary — below market by design at seed stage.
B7: Leadership | C7: CTO (technical co-founder) | D7: 1 | E7: 100000 | F7: 0 | G7: =D7*E7 -> 100000 | H7: =G7*F7 -> 0 | I7: =MAX(0,(E7+E7*F7)-Assumptions!$C$33)*Assumptions!$C$32*D7 -> 14250 | J7: =(G7+H7)*(Assumptions!$C$34+Assumptions!$C$35) -> 13000 | K7: =G7+H7+I7+J7 -> 127250 | L7: Founder salary — below market by design at seed stage.
B8: Credit | C8: Senior underwriter (human-in-the-loop) | D8: 2 | E8: 65000 | F8: 0.15 | G8: =D8*E8 -> 130000 | H8: =G8*F8 -> 19500 | I8: =MAX(0,(E8+E8*F8)-Assumptions!$C$33)*Assumptions!$C$32*D8 -> 20925 | J8: =(G8+H8)*(Assumptions!$C$34+Assumptions!$C$35) -> 19435 | K8: =G8+H8+I8+J8 -> 189860 | L8: Same band as traditional senior UW. Reviews AI-drafted packs, owns the decision.
B9: Operations | C9: Completions & servicing lead | D9: 1 | E9: 42500 | F9: 0.05 | G9: =D9*E9 -> 42500 | H9: =G9*F9 -> 2125 | I9: =MAX(0,(E9+E9*F9)-Assumptions!$C$33)*Assumptions!$C$32*D9 -> 5943.75 | J9: =(G9+H9)*(Assumptions!$C$34+Assumptions!$C$35) -> 5801.25 | K9: =G9+H9+I9+J9 -> 56370 | L9: One person runs completions and servicing with automated workflow.
B10: Compliance | C10: Compliance officer (SMF16/17) | D10: 1 | E10: 67500 | F10: 0.125 | G10: =D10*E10 -> 67500 | H10: =G10*F10 -> 8437.5 | I10: =MAX(0,(E10+E10*F10)-Assumptions!$C$33)*Assumptions!$C$32*D10 -> 10640.625 | J10: =(G10+H10)*(Assumptions!$C$34+Assumptions!$C$35) -> 9871.875 | K10: =G10+H10+I10+J10 -> 96450 | L10: Regulated lender needs one regardless of size.
B11: Sales | C11: BDM / broker relationships | D11: 1 | E11: 65000 | F11: 0.4 | G11: =D11*E11 -> 65000 | H11: =G11*F11 -> 26000 | I11: =MAX(0,(E11+E11*F11)-Assumptions!$C$33)*Assumptions!$C$32*D11 -> 12900 | J11: =(G11+H11)*(Assumptions!$C$34+Assumptions!$C$35) -> 11830 | K11: =G11+H11+I11+J11 -> 115730 | L11: One BDM; brokers still introduce ~85% of flow.
B12: Technology | C12: Software / ML engineer | D12: 1 | E12: 65000 | F12: 0.05 | G12: =D12*E12 -> 65000 | H12: =G12*F12 -> 3250 | I12: =MAX(0,(E12+E12*F12)-Assumptions!$C$33)*Assumptions!$C$32*D12 -> 9487.5 | J12: =(G12+H12)*(Assumptions!$C$34+Assumptions!$C$35) -> 8872.5 | K12: =G12+H12+I12+J12 -> 86610 | L12: Maintains pipelines, evals, integrations.
B13: TOTAL PEOPLE COST | D13: =SUM(D6:D12) -> 8 | G13: =SUM(G6:G12) -> 570000 | H13: =SUM(H6:H12) -> 59312.5 | I13: =SUM(I6:I12) -> 88396.875 | J13: =SUM(J6:J12) -> 81810.625 | K13: =SUM(K6:K12) -> 799520
B15: Office (desks × cost per desk) | K15: =D13*Assumptions!$C$36 -> 76800
B16: Software & data seats | K16: =D13*Assumptions!$C$37 -> 24000
B17: AI model cost (cases × £ per case) | K17: =Assumptions!$C$15*Assumptions!$C$39 -> 11584
B18: Data & verification (cases × £ per case) | K18: =Assumptions!$C$15*Assumptions!$C$40 -> 36200
B19: Platform, hosting, monitoring | K19: =Assumptions!$C$41 -> 60000

Sheet Salary benchmarks
B2: Industry salary benchmarks — London, specialist lender, 2025–26
B3: Research ranges from job ads and salary guides (see Sources). 'Used' is the figure in the headcount sheets; founder input overrides the market midpoint where they differ.
B5: Role | C5: Level | D5: Low | E5: Mid | F5: High | G5: Used | H5: Bonus % (mid)
B6: Credit analyst / underwriter | C6: Junior | D6: 30000 | E6: 37500 | F6: 45000 | G6: 35000 | H6: 0.05 | I6: Fame Recruitment ad; talent.com
B7: Credit analyst / underwriter | C7: Mid | D7: 45000 | E7: 55000 | F7: 65000 | G7: 50000 | H7: 0.15 | I7: Tandem; Fintelligent job ads — founder: analysts normally under £55k
B8: Credit analyst / underwriter | C8: Senior | D8: 65000 | E8: 75000 | F8: 85000 | G8: 65000 | H8: 0.15 | I8: exec-appointments; Fintelligent
B9: Credit manager | C9: Manager | D9: 65000 | E9: 72500 | F9: 85000 | G9: not in team | H9: 0.15 | I9: Fintelligent
B10: Head of credit | C10: Head | D10: 100000 | E10: 115000 | F10: 130000 | G10: 115000 | H10: 0.25 | I10: jobsite; Morgan McKinley (estimate)
B11: Case manager | C11: Junior/mid | D11: 30000 | E11: 35000 | F11: 40000 | G11: not in team | H11: 0.05 | I11: NRG ad
B12: Completions specialist | C12: Mid | D12: 35000 | E12: 42500 | F12: 50000 | G12: 42500 | H12: 0.05 | I12: Stellar Select (London uplift estimated)
B13: Loan administrator / servicing | C13: Junior | D13: 26000 | E13: 32000 | F13: 38000 | G13: 32000 | H13: 0.025 | I13: Indeed; PayScale
B14: Portfolio manager | C14: Mid/senior | D14: 50000 | E14: 57500 | F14: 65000 | G14: 57500 | H14: 0.125 | I14: Reed; Fintelligent
B15: BDM | C15: Mid | D15: 55000 | E15: 65000 | F15: 80000 | G15: 65000 | H15: 0.4 | I15: Fintelligent; Totaljobs (OTE 1.3–1.8x)
B16: Senior BDM / originator | C16: Senior | D16: 75000 | E16: 85000 | F16: 90000 | G16: 85000 | H16: 0.6 | I16: Fintelligent; jobsite
B17: Head of sales | C17: Head | D17: 90000 | E17: 110000 | F17: 130000 | G17: 110000 | H17: 0.35 | I17: Glassdoor; bridgingloandirectory (estimate)
B18: Marketing executive | C18: Junior/mid | D18: 30000 | E18: 36000 | F18: 43000 | G18: 36000 | H18: 0.025 | I18: Glassdoor
B19: Marketing manager | C19: Manager | D19: 41000 | E19: 48000 | F19: 57000 | G19: 48000 | H19: 0.075 | I19: Glassdoor
B20: CEO / MD | C20: C-suite | D20: 150000 | E20: 200000 | F20: 250000 | G20: 200000 | H20: 0.4 | I20: Exec Capital (estimate; owner-MDs often take less + dividends)
B21: CFO / FD | C21: C-suite | D21: 110000 | E21: 140000 | F21: 170000 | G21: 140000 | H21: 0.225 | I21: FD Capital (estimate)
B22: CTO / Head of technology | C22: Head | D22: 90000 | E22: 115000 | F22: 140000 | G22: 115000 | H22: 0.15 | I22: Glassdoor (estimate)
B23: COO / Operations director | C23: Director | D23: 80000 | E23: 100000 | F23: 120000 | G23: 100000 | H23: 0.225 | I23: Exec Capital (estimate)
... B25: Compliance officer | C25: Mid/senior | D25: 60000 | E25: 67500 | F25: 75000 | G25: 67500 | H25: 0.125 | I25: Morgan McKinley 2026
B27: Employer on-costs used: NI 15% above £5,000; pension 5%; other 8% → fully loaded ≈ 1.28× base + bonus. London desk £9,600/yr.

Sheet Revenue
B2: Revenue build — identical for both models (same book, same pricing)
B4: Line | C4: £ per year | D4: Formula / note
B5: Annual originations | C5: =Assumptions!$C$13 -> 150230000 | D5: Loans × average loan size
B6: Average live loan book | C6: =Assumptions!$C$6 -> 150000000
B8: Arrangement fee charged (gross) | C8: =C5*Assumptions!$C$19 -> 3004600 | D8: Originations × arrangement fee %
B9: Less: introducer / broker share of arrangement fee | C9: =-C5*(Assumptions!$C$19-Assumptions!$C$20)*Assumptions!$C$25 -> -1915432.5 | D9: Paid away to brokers on broker-introduced loans
B10: Gross interest income | C10: =C6*Assumptions!$C$18 -> 16200000 | D10: Book × annualised borrower rate
B11: Admin, drawdown and redemption fees | C11: =Assumptions!$C$12*(Assumptions!$C$21+Assumptions!$C$22) -> 543000 | D11: Loans × (admin fee + redemption/drawdown fees)
B12: Exit fee income | C12: =C5*Assumptions!$C$23 -> 0 | D12: Originations × exit fee %
B13: Other fee income | C13: =C5*Assumptions!$C$24 -> 300460 | D13: Extensions, variations, non-redemption
B14: GROSS REVENUE (after broker share) | C14: =SUM(C8:C13) -> 18132628
B16: Less: cost of funds (funding partner buy rate) | C16: =-C6*Assumptions!$C$28*Assumptions!$C$27 -> -12468750 | D16: Book × partner-funded share × buy rate
B17: Less: funder fees | C17: =-Assumptions!$C$12*Assumptions!$C$29 -> -90500 | D17: Loans × partner fee per deal
B18: Less: expected credit losses | C18: =-C6*Assumptions!$C$30 -> -750000 | D18: Book × annual loss rate
B19: NET REVENUE (after funding, brokers, losses) | C19: =C14+SUM(C16:C18) -> 4823377.5 | D19: This is what has to pay for people, premises and technology
B21: Net revenue as % of book | C21: =C19/C6 -> 0.03215585
B22: Net revenue per completed loan | C22: =C19/Assumptions!$C$12 -> 26648.494
B23: Net interest margin (% of book) | C23: =(C10+C16)/C6 -> 0.024875 | D23: Gross interest less cost of funds. Founder calculator example: 3.4% of facility over 18 months.

Sheet Comparison
B2: Same loan book, two operating models
C4: Northgate Bridging (traditional) | D4: Verdigris (AI-native) | E4: Difference | F4: Note
B5: Headcount (FTE) | C5: ='Headcount - Traditional'!D24 -> 37 | D5: ='Headcount - AI-native'!D13 -> 8 | E5: =D5-C5 -> -29
B6: People cost (fully loaded) | C6: ='Headcount - Traditional'!K24 -> 3638490 | D6: ='Headcount - AI-native'!K13 -> 799520 | E6: =D6-C6 -> -2838970 | F6: Traditional: 37 people. AI-native: 8 people, AI does reading/reconciling/drafting.
B7: Office | C7: ='Headcount - Traditional'!K26 -> 355200 | D7: ='Headcount - AI-native'!K15 -> 76800 | E7: =D7-C7 -> -278400
B8: Software & data seats | C8: ='Headcount - Traditional'!K27 -> 111000 | D8: ='Headcount - AI-native'!K16 -> 24000 | E8: =D8-C8 -> -87000
B9: Data & verification per case | C9: ='Headcount - Traditional'!K28 -> 36200 | D9: ='Headcount - AI-native'!K18 -> 36200 | E9: =D9-C9 -> 0
B10: AI model cost | C10: =0 -> 0 | D10: ='Headcount - AI-native'!K17 -> 11584 | E10: =D10-C10 -> 11584
B11: Platform, hosting, monitoring | C11: =0 -> 0 | D11: ='Headcount - AI-native'!K19 -> 60000 | E11: =D11-C11 -> 60000 | F11: Model cost ≈ £16/case ×10 safety factor already included; see Assumptions.
B12: TOTAL OPERATING COST | C12: =SUM(C6:C11) -> 4140890 | D12: =SUM(D6:D11) -> 1008104 | E12: =D12-C12 -> -3132786
B14: Net revenue (from Revenue sheet) | C14: =Revenue!C19 -> 4823377.5 | D14: =Revenue!C19 -> 4823377.5 | E14: =D14-C14 -> 0
B15: OPERATING PROFIT (before tax) | C15: =C14-C12 -> 682487.5 | D15: =D14-D12 -> 3815273.5 | E15: =D15-C15 -> 3132786
B16: Operating margin (% of net revenue) | C16: =C15/C14 -> 0.14149577 | D16: =D15/D14 -> 0.79099625 | E16: =D16-C16 -> 0.64950048
B18: Loans completed per year | C18: =Assumptions!$C$12 -> 181 | D18: =Assumptions!$C$12 -> 181
B19: Operating cost per completed loan | C19: =C12/Assumptions!$C$12 -> 22877.845 | D19: =D12/Assumptions!$C$12 -> 5569.6354 | E19: =D19-C19 -> -17308.21 | F19: Same loans, same revenue: the difference is entirely operating cost.
B20: Operating cost as % of originations | C20: =C12/Assumptions!$C$13 -> 0.027563669 | D20: =D12/Assumptions!$C$13 -> 0.006710404 | E20: =D20-C20 -> -0.020853265 | F20: Cost to originate. Traditional lenders typically 1.5–3% of volume.
B21: Loan book per employee | C21: =Assumptions!$C$6/C5 -> 4054054.1 | D21: =Assumptions!$C$6/D5 -> 18750000 | E21: =D21-C21 -> 14695946
B22: Loans completed per employee per year | C22: =Assumptions!$C$12/C5 -> 4.8918919 | D22: =Assumptions!$C$12/D5 -> 22.625 | E22: =D22-C22 -> 17.733108
B25: Scaling: what happens as the book grows (same pricing, same loss rate)
B26: Traditional: management fixed, every other function grows in proportion to the book. AI-native: fixed core team + 1 underwriter per £75m of book + 1 BDM per £150m; AI cost grows with cases.
B27: Metric | C27: Book £150m | D27: Book £300m | E27: Book £600m | F27: Note
B28: Loan book | C28: 150000000 | D28: 300000000 | E28: 600000000 | F28: Scale factor vs base = book ÷ Assumptions book
B29: Scale factor vs base case | C29: =C28/Assumptions!$C$6 -> 1 | D29: =D28/Assumptions!$C$6 -> 2 | E29: =E28/Assumptions!$C$6 -> 4
B30: Loans completed per year | C30: =ROUND(Assumptions!$C$12*C29,0) -> 181 | D30: =ROUND(Assumptions!$C$12*D29,0) -> 362 | E30: =ROUND(Assumptions!$C$12*E29,0) -> 724
B31: Net revenue | C31: =Revenue!$C$19*C29 -> 4823377.5 | D31: =Revenue!$C$19*D29 -> 9646755 | E31: =Revenue!$C$19*E29 -> 19293510
B33: TRADITIONAL
B34: Headcount | C34: =SUMIF('Headcount - Traditional'!B6:B23,"Management",'Headcount - Traditional'!D6:D23)+('Headcount - Traditional'!$D$24-SUMIF('Headcount - Traditional'!B6:B23,"Management",'Headcount - Traditional'!D6:D23))*C29 -> 37 | D34: =SUMIF('Headcount - Traditional'!B6:B23,"Management",'Headcount - Traditional'!D6:D23)+('Headcount - Traditional'!$D$24-SUMIF('Headcount - Traditional'!B6:B23,"Management",'Headcount - Traditional'!D6:D23))*D29 -> 69 | E34: =SUMIF('Headcount - Traditional'!B6:B23,"Management",'Headcount - Traditional'!D6:D23)+('Headcount - Traditional'!$D$24-SUMIF('Headcount - Traditional'!B6:B23,"Management",'Headcount - Traditional'!D6:D23))*E29 -> 133
B35: Operating cost | C35: =SUMIF('Headcount - Traditional'!B6:B23,"Management",'Headcount - Traditional'!K6:K23)+('Headcount - Traditional'!$K$24-SUMIF('Headcount - Traditional'!B6:B23,"Management",'Headcount - Traditional'!K6:K23))*C29+C34*(Assumptions!$C$36+Assumptions!$C$37)+Assumptions!$C$15*C29*Assumptions!$C$40 -> 4140890 | D35: =SUMIF('Headcount - Traditional'!B6:B23,"Management",'Headcount - Traditional'!K6:K23)+('Headcount - Traditional'!$K$24-SUMIF('Headcount - Traditional'!B6:B23,"Management",'Headcount - Traditional'!K6:K23))*D29+D34*(Assumptions!$C$36+Assumptions!$C$37)+Assumptions!$C$15*D29*Assumptions!$C$40 -> 7221330 | E35: =SUMIF('Headcount - Traditional'!B6:B23,"Management",'Headcount - Traditional'!K6:K23)+('Headcount - Traditional'!$K$24-SUMIF('Headcount - Traditional'!B6:B23,"Management",'Headcount - Traditional'!K6:K23))*E29+E34*(Assumptions!$C$36+Assumptions!$C$37)+Assumptions!$C$15*E29*Assumptions!$C$40 -> 13382210
B36: Operating profit | C36: =C31-C35 -> 682487.5 | D36: =D31-D35 -> 2425425 | E36: =E31-E35 -> 5911300
B37: Operating margin | C37: =C36/C31 -> 0.14149577 | D37: =D36/D31 -> 0.25142392 | E37: =E36/E31 -> 0.306388
B38: Cost per completed loan | C38: =C35/C30 -> 22877.845 | D38: =D35/D30 -> 19948.425 | E38: =E35/E30 -> 18483.715
B40: AI-NATIVE
B41: Headcount | C41: =(SUM('Headcount - AI-native'!D6:D12)-'Headcount - AI-native'!D8-'Headcount - AI-native'!D11)+ROUNDUP(C28/75000000,0)+ROUNDUP(C28/150000000,0) -> 8 | D41: =(SUM('Headcount - AI-native'!D6:D12)-'Headcount - AI-native'!D8-'Headcount - AI-native'!D11)+ROUNDUP(D28/75000000,0)+ROUNDUP(D28/150000000,0) -> 11 | E41: =(SUM('Headcount - AI-native'!D6:D12)-'Headcount - AI-native'!D8-'Headcount - AI-native'!D11)+ROUNDUP(E28/75000000,0)+ROUNDUP(E28/150000000,0) -> 17
B42: Operating cost | C42: =(SUM('Headcount - AI-native'!K6:K12)-'Headcount - AI-native'!K8-'Headcount - AI-native'!K11)+ROUNDUP(C28/75000000,0)*('Headcount - AI-native'!K8/'Headcount - AI-native'!D8)+ROUNDUP(C28/150000000,0)*('Headcount - AI-native'!K11/'Headcount - AI-native'!D11)+C41*(Assumptions!$C$36+Assumptions!$C$37)+Assumptions!$C$15*C29*(Assumptions!$C$39+Assumptions!$C$40)+Assumptions!$C$41*(1+0.5*(C29-1)) -> 1008104 | D42: =(SUM('Headcount - AI-native'!K6:K12)-'Headcount - AI-native'!K8-'Headcount - AI-native'!K11)+ROUNDUP(D28/75000000,0)*('Headcount - AI-native'!K8/'Headcount - AI-native'!D8)+ROUNDUP(D28/150000000,0)*('Headcount - AI-native'!K11/'Headcount - AI-native'!D11)+D41*(Assumptions!$C$36+Assumptions!$C$37)+Assumptions!$C$15*D29*(Assumptions!$C$39+Assumptions!$C$40)+Assumptions!$C$41*(1+0.5*(D29-1)) -> 1429278 | E42: =(SUM('Headcount - AI-native'!K6:K12)-'Headcount - AI-native'!K8-'Headcount - AI-native'!K11)+ROUNDUP(E28/75000000,0)*('Headcount - AI-native'!K8/'Headcount - AI-native'!D8)+ROUNDUP(E28/150000000,0)*('Headcount - AI-native'!K11/'Headcount - AI-native'!D11)+E41*(Assumptions!$C$36+Assumptions!$C$37)+Assumptions!$C$15*E29*(Assumptions!$C$39+Assumptions!$C$40)+Assumptions!$C$41*(1+0.5*(E29-1)) -> 2271626 | F42: Platform cost grows at half the rate of the book.
B43: Operating profit | C43: =C31-C42 -> 3815273.5 | D43: =D31-D42 -> 8217477 | E43: =E31-E42 -> 17021884
B44: Operating margin | C44: =C43/C31 -> 0.79099625 | D44: =D43/D31 -> 0.85183847 | E44: =E43/E31 -> 0.88225958
B45: Cost per completed loan | C45: =C42/C30 -> 5569.6354 | D45: =D42/D30 -> 3948.2818 | E45: =E42/E30 -> 3137.605
B47: AI-native cost advantage (traditional ÷ AI-native) | C47: =C35/C42 -> 4.107602 | D47: =D35/D42 -> 5.0524321 | E47: =E35/E42 -> 5.891027
B48: Extra operating profit from AI-native model | C48: =C43-C36 -> 3132786 | D48: =D43-D36 -> 5792052 | E48: =E43-E36 -> 11110584

Sheet Per-case cost
B2: What it costs to underwrite one case
B4: Item | C4: Traditional | D4: AI-native | E4: Note
B5: Fully loaded underwriter cost per hour | C5: =SUM('Headcount - Traditional'!K7:K8)/SUM('Headcount - Traditional'!D7:D8)/Assumptions!$C$44 -> 47.319192 | D5: =SUM('Headcount - Traditional'!K7:K8)/SUM('Headcount - Traditional'!D7:D8)/Assumptions!$C$44 -> 47.319192 | E5: Blended senior + mid underwriter, fully loaded, ÷ productive hours.
B6: Underwriter hours per assessed case | C6: =Assumptions!$C$43 -> 12 | D6: =Assumptions!$C$42 -> 1.5 | E6: Traditional: reading, reconciling, chasing, drafting. AI-native: review and decide.
B7: Human cost per case | C7: =C5*C6 -> 567.8303 | D7: =D5*D6 -> 70.978788
B8: AI model cost per case | C8: =0 -> 0 | D8: =Assumptions!$C$39 -> 16 | E8: Includes 10x safety factor.
B9: Data & verification per case | C9: =Assumptions!$C$40 -> 50 | D9: =Assumptions!$C$40 -> 50 | E9: Same searches either way.
B10: TOTAL COST PER ASSESSED CASE | C10: =SUM(C7:C9) -> 617.8303 | D10: =SUM(D7:D9) -> 136.97879
B12: Cases one underwriter can assess per year | C12: =Assumptions!$C$44/C6 -> 137.5 | D12: =Assumptions!$C$44/D6 -> 1100 | E12: Productive hours ÷ hours per case.
B13: Elapsed time to first credit view | C13: 5 | D13: 0.25 | E13: Working days. Traditional: founder experience 3–7 days to a credit view. AI-native: hours. Input cells.
B14: Cost reduction per case | D14: =1-D10/C10 -> 0.7782906
B16: Capacity multiple per underwriter | D16: =C6/D6 -> 8 | E16: Traditional hours per case ÷ AI-native review hours per case. Agents hold the file while it waits on third parties.
B17: Live cases one underwriter can carry (low) | C17: =Assumptions!$C$46 -> 15 | D17: =C17*$D$16 -> 120 | E17: Today's caseload × capacity multiple.
B18: Live cases one underwriter can carry (high) | C18: =Assumptions!$C$47 -> 25 | D18: =C18*$D$16 -> 200 | E18: The headline: 15–25 live deals today → 120–200 with agents. Beyond 200 needs review time below 1.5 h; not assumed.

Sheet Sources
B2: Sources
B4: Topic | C4: Source
B5: Bridging market: BDLA loan books & completions | C5: Mortgage Solutions, 12 Jun 2026 — https://www.mortgagesolutions.co.uk/specialist-lending/bridging/2026/06/12/bridging-market-softens-as-growth-tapers-off-bdla-finds/
B6: Bridging market: BDLA Q4 2025 | C6: https://thebdla.org/news/bridging-market-maintains-momentum-in-2025/
B7: Bridging market: average loan £540k | C7: MPA Mag — https://www.mpamag.com/uk/mortgage-types/bridging/bdla-reports-strong-start-for-bridging-finance-in-2025/539187
B8: Bridging Trends 2025 (rate 0.84%, LTV 55%, 43 days, term 12m) | C8: MT Finance — https://www.mt-finance.com/speed-and-stability-bridging-loan-completion-times-hit-eight-year-low-in-2025/
B9: Bridging Trends Q2 2026 (rate 0.81%) | C9: https://www.mt-finance.com/bridging-trends-savvy-borrowers-focus-on-speed-and-equity-release-in-q2/
B10: Broker channel share (61% primary, 15% direct) | C10: Mortgage Solutions, 9 Jun 2026 — https://www.mortgagesolutions.co.uk/specialist-lending/bridging/2026/06/09/bridging-lenders-say-the-market-is-still-growing-survey-finds/
B11: Broker fees / arrangement fee norms | C11: Bridging Loan Directory fee guide — https://bridgingloandirectory.co.uk/guides/bridging-loan-fees-explained-full-cost-breakdown-2025-guide/
B12: Broker commission benchmark (1.5% avg) | C12: Bridging & Commercial, Octane £2bn milestone — https://bridgingandcommercial.co.uk/article/21707/octane-surpasses-%C2%A32bn-lending-milestone
B13: Loan book per employee benchmarks | C13: Octane (~30 staff), Hope Capital (32–41), Tuscan (19) — see company press; Tracxn/LinkedIn headcounts
B14: Salaries: underwriters | C14: Fintelligent, Tandem, exec-appointments job ads 2025–26; talent.com; Reed
B15: Salaries: portfolio, completions, admin | C15: Reed, Fintelligent, NRG, Stellar Select ads; Indeed; PayScale
... B29: Founder data: pipeline tracker (Jan 2026, anonymised) | C29: ~20 live cases; facilities £205k–£1.59m, median ≈ £440k; weekly status dominated by chasing valuers, monitoring surveyors and solicitors
